<?xml version="1.0"?>

<robot xmlns:xacro="http://www.ros.org/wiki/xacro" name="cap_openner">

    <xacro:include filename="$(find abb_gofa_description)/urdf/cap_openner/cap_openner_ros2_control.urdf.xacro" />
    <xacro:cap_openner_ros2_control/>

  <link name="world"></link>
  <link name="openner_base">
    <inertial>
      <mass value="1"/>
      <origin xyz="0 0 0"/>
      <inertia ixx="0.1" ixy="0" ixz="0" iyy="0.1" iyz="0" izz="0.1"/>
    </inertial>
    <visual>
      <geometry>
        <mesh filename="file://$(find abb_gofa_description)/meshes/cap_openner/openner_base.dae"/>
      </geometry>
    </visual>
    <collision>
      <geometry>
        <mesh filename="file://$(find abb_gofa_description)/meshes/cap_openner/openner_base.dae"/>
      </geometry>
    </collision>
  </link>

  <link name="gripper_link">
    <inertial>
      <mass value="0.5"/>
      <origin xyz="0 0 0"/>
      <inertia ixx="0.1" ixy="0" ixz="0" iyy="0.1" iyz="0" izz="0.1"/>
    </inertial>
    <visual>
      <geometry>
        <mesh filename="file://$(find abb_gofa_description)/meshes/cap_openner/gripper_link.dae"/>
      </geometry>
    </visual>
    <collision>
      <geometry>
        <mesh filename="file://$(find abb_gofa_description)/meshes/cap_openner/gripper_link.dae"/>
      </geometry>
    </collision>
  </link>

  <link name="gripper_base">
    <inertial>
      <mass value="0.3"/>
      <origin xyz="0 0 0"/>
      <inertia ixx="0.1" ixy="0" ixz="0" iyy="0.1" iyz="0" izz="0.1"/>
    </inertial>
    <visual>
      <geometry>
        <mesh filename="file://$(find abb_gofa_description)/meshes/cap_openner/gripper_base.dae"/>
      </geometry>
    </visual>
    <collision>
      <geometry>
        <mesh filename="file://$(find abb_gofa_description)/meshes/cap_openner/gripper_base.dae"/>
      </geometry>
    </collision>
  </link>

  <link name="left_gripper">
    <inertial>
      <mass value="0.3"/>
      <origin xyz="0 0 0"/>
      <inertia ixx="0.1" ixy="0" ixz="0" iyy="0.1" iyz="0" izz="0.1"/>
    </inertial>
    <visual>
      <geometry>
        <mesh filename="file://$(find abb_gofa_description)/meshes/cap_openner/left_gripper.dae"/>
      </geometry>
    </visual>
    <collision>
      <geometry>
        <mesh filename="file://$(find abb_gofa_description)/meshes/cap_openner/left_gripper.dae"/>
      </geometry>
    </collision>
  </link>

  <link name="right_gripper">
    <inertial>
      <mass value="0.3"/>
      <origin xyz="0 0 0" rpy="0.0 0.0 0.0"/>
      <inertia ixx="0.1" ixy="0" ixz="0" iyy="0.1" iyz="0" izz="0.1"/>
    </inertial>
    <visual>
      <geometry>
        <mesh filename="file://$(find abb_gofa_description)/meshes/cap_openner/right_gripper.dae"/>
      </geometry>
    </visual>
    <collision>
      <geometry>
        <mesh filename="file://$(find abb_gofa_description)/meshes/cap_openner/right_gripper.dae"/>
      </geometry>
    </collision>
  </link>

  <joint name="world2base" type="fixed">
    <origin xyz="0.9 0  0.71" rpy="0.0 0.0 1.57079"/>
    <parent link="world"/>
    <child link="openner_base"/>
  </joint>

  <joint name="base2link" type="prismatic">
    <origin xyz="0.0 0.025 0.23" rpy="0.0 0.0 -1.5707"/>
    <parent link="openner_base"/>
    <child link="gripper_link"/>
    <axis xyz="0.0 0.0 1"/>
    <limit lower="-0.14" upper="0.01" effort="1" velocity="0.5"/>
  </joint>

  <joint name="link2base" type="continuous">
    <origin xyz="0.0 0.0 -0.045" rpy="0.0 0.0 1.5707"/>
    <parent link="gripper_link"/>
    <child link="gripper_base"/>
    <axis xyz="0.0 0.0 1"/>
  </joint>

  <joint name="left_gripper2base" type="prismatic">
    <origin xyz="-0.0475 0.0 -0.015" rpy="0.0 0.0 0.0"/>
    <parent link="gripper_base"/>
    <child link="left_gripper"/>
    <axis xyz="1.0 0.0 0.0"/>
    <limit lower="0" upper="0.0275" effort="1.0" velocity="0.5"/>
  </joint>

  <joint name="right_gripper2base" type="prismatic">
    <origin xyz="0.0475 0.0 -0.015" rpy="0.0 0.0 3.1415926"/>
    <parent link="gripper_base"/>
    <child link="right_gripper"/>
    <axis xyz="1.0 0.0 0.0"/>
    <limit lower="0" upper="0.0275" effort="1.0" velocity="0.5"/>
  </joint>
</robot>
