<robot name="pipette">
    <link name="world"></link>
    <link name="pipette_base">
        <inertial>
        <mass value="0.1"/>
        <origin xyz="0 0 0"/>
        <inertia ixx="0.1" ixy="0" ixz="0" iyy="0.1" iyz="0" izz="0.1"/>
        </inertial>
        <visual>
        <geometry>
            <mesh filename="file://$(find abb_gofa_description)/meshes/pipette/pipette_base.dae"/>
        </geometry>
        </visual>
        <collision>
        <geometry>
            <mesh filename="file://$(find abb_gofa_description)/meshes/pipette/pipette_base.dae"/>
        </geometry>
        </collision>
    </link>

    <link name="pipette_link">
        <inertial>
        <mass value="0.00001"/>
        <origin xyz="0 0 0"/>
        <inertia ixx="0.00001" ixy="0" ixz="0" iyy="0.00001" iyz="0" izz="0.00001"/>
        </inertial>
        <visual>
        <geometry>
            <mesh filename="file://$(find abb_gofa_description)/meshes/pipette/pipette_link.dae"/>
        </geometry>
        </visual>
        <collision>
        <geometry>
            <mesh filename="file://$(find abb_gofa_description)/meshes/pipette/pipette_link.dae"/>
        </geometry>
        </collision>
    </link>

    <link name="pipette_clicker">
        <inertial>
        <mass value="0.00001"/>
        <origin xyz="0 0 0"/>
        <inertia ixx="0.00001" ixy="0" ixz="0" iyy="0.00001" iyz="0" izz="0.00001"/>
        </inertial>
        <visual>
        <geometry>
            <mesh filename="file://$(find abb_gofa_description)/meshes/pipette/pipette_clicker.dae"/>
        </geometry>
        </visual>
        <collision>
        <geometry>
            <mesh filename="file://$(find abb_gofa_description)/meshes/pipette/pipette_clicker.dae"/>
        </geometry>
        </collision>
    </link>

    <link name="pipette_body">
        <inertial>
        <mass value="0.00001"/>
        <origin xyz="0 0 0"/>
        <inertia ixx="0.00001" ixy="0" ixz="0" iyy="0.00001" iyz="0" izz="0.00001"/>
        </inertial>
        <visual>
        <geometry>
            <mesh filename="file://$(find abb_gofa_description)/meshes/pipette/pipette_body.dae"/>
        </geometry>
        </visual>
        <collision>
        <geometry>
            <mesh filename="file://$(find abb_gofa_description)/meshes/pipette/pipette_body.dae"/>
        </geometry>
        </collision>
    </link>

    <link name="pipette_nib">
        <inertial>
        <mass value="0.00001"/>
        <origin xyz="0 0 0"/>
        <inertia ixx="0.00001" ixy="0" ixz="0" iyy="0.00001" iyz="0" izz="0.00001"/>
        </inertial>
        <visual>
        <geometry>
            <mesh filename="file://$(find abb_gofa_description)/meshes/pipette/pipette_nib.dae"/>
        </geometry>
        </visual>
        <collision>
        <geometry>
            <mesh filename="file://$(find abb_gofa_description)/meshes/pipette/pipette_nib.dae"/>
        </geometry>
        </collision>
    </link>

    <joint name="world2base" type="fixed">
        <origin xyz="0.0 0.0 0.135" rpy="3.1415926 0.0 0.0"/>
        <parent link="world"/>
        <child link="pipette_base"/>
    </joint>

    <joint name="base2link" type="prismatic">
        <origin xyz="0.044 0.0 0.060" rpy="3.1415926 0.0 1.5707"/>
        <parent link="pipette_base"/>
        <child link="pipette_link"/>
        <axis xyz="0.0 0.0 1"/>
        <limit lower="-0.02" upper="-0.01" effort="1" velocity="0.5"/>
    </joint>

    <joint name="link2clicker" type="fixed">
        <origin xyz="0.0 0.0375 -0.027" rpy="0.0 0.0 0.0"/>
        <parent link="pipette_link"/>
        <child link="pipette_clicker"/>
    </joint>

    <joint name="base2body" type="fixed">
        <origin xyz="0.082 0.0 0.10" rpy="0.0 3.1415926 0.0"/>
        <parent link="pipette_base"/>
        <child link="pipette_body"/>
    </joint>

    <joint name="body2nib" type="fixed">
        <origin xyz="0.0 0.0 -0.075" rpy="0.0 3.1415926 0.0"/>
        <parent link="pipette_body"/>
        <child link="pipette_nib"/>
    </joint>

</robot>




